Workbook

Sheet LUCRO REAL
A1: Demonstração do Resultado do Exercício Comparativa Reforma - Lucro Real
A2: www.reformatributaria.inf.br
A3: Faturamento antes Reforma PROD | B3: 0.0001 | D3: Despesas R$ | E3: 2500 | F3: =E3/I3 -> 0.05 | I3: =B3+B4 -> 50000
A4: Faturamento antes Reforma Serviço | B4: 50000 | D4: Custo Serviços Prest.R$ | E4: 35000 | F4: =E4/B4 -> 0.7 | G4: =81/148 -> 0.5472973
B5: Impostos Extintos (PIS, COFINS, ICMS, IPI,ISSQN)* | C5: 0.0678 | D5: CMV R$ | E5: 1e-05 | F5: =E5/B3 -> 0.1
A6: Faturamento Pós-Reforma | B6: =I3-I3*C5 -> 46610
A7: Percentual Desp. c/ Dir. a Crédito de IBS/CBS | B7: 0.7 | D7: Redução ICMS/ISS/Pis/Cof Desp. | E7: =7%+5%+5%+3.65% -> 0.2065 | N7: 100
A8: Imp. Extintos (PIS, COFINS, ICMS, IPI,ISS) CMV | B8: =7%+3.65%+10%+3.5% -> 0.2415
A9: Alíquota IBS/CBS | B9: 0.28 | D9: IRPJ e CSLL Percentual | E9: 0.24 | N9: 10 | O9: ipi
N10: 15 | O10: icms
A11: Demonstração do Resultado do Exercício Comparativa - Lucro REAL | N11: 3.65 | O11: pis/cofins
N12: =SUM(N9:N11) -> 28.65 | O12: =+N7-N12 -> 71.35
A13: Descrição | B13: Antes | C13: % | D13: Depois | E13: % | G13: Teste de Redução dos Valores após reforma | O13: =+O12*1.27 -> 90.6145
A14: Receita Bruta | B14: =+I3 -> 50000 | C14: =B14/$B$14 -> 1 | D14: =+B16 -> 46610 | E14: =D14/$D$14 -> 1 | I14: Desp. | J14: CMV | K14: CSV
A15: (-) Deduções (ICMS, PIS, COFINS, ISS, IPI) | B15: =-I3*C5 -> -3390 | C15: =B15/$B$14 -> -0.0678 | D15: 0 | E15: =D15/$D$14 -> 0 | H15: Total Despesas Antes | I15: =I3*F3 -> 2500 | J15: =B3*F5 -> 1e-05 | K15: =+B4*F4 -> 35000
A16: Receita Líquida | B16: =SUM(B14:B15) -> 46610 | C16: =B16/$B$14 -> 0.9322 | D16: =SUM(D14:D15) -> 46610 | E16: =D16/$D$14 -> 1 | H16: Redução de Impostos Extintos | I16: =-(I15*B7*E7) -> -361.375 | J16: =-J15*$B$8 -> -2.415e-06 | K16: =-(K15*B7*E7) -> -5059.25 | L16: (Estou considerando bases diferentes para dedução dos impostos sobre CMV e CSV, poisno caso do CMV reduz os mesmos impostos que a empresa informou para seus produtos/serviços , e no caso dos serviços, reduzindo os impostos sobre tudo que não e mão de obra (a diferença entre 100% e o percentual informado com direito a crédito
A17: (=) CMV + (CSV) | B17: =-F5*B3-B4*F4 -> -35000 | C17: =B17/$B$14 -> -0.7 | D17: =-J17-K17 -> -29940.75 | E17: =D17/$D$14 -> -0.64236752 | F17: ** | H17: Desp. (-) Impostos | I17: =SUM(I15:I16) -> 2138.625 | J17: =SUM(J15:J16) -> 7.585e-06 | K17: =SUM(K15:K16) -> 29940.75
A18: Margem de Contribuição | B18: =SUM(B16:B17) -> 11610 | C18: =B18/$B$14 -> 0.2322 | D18: =SUM(D16:D17) -> 16669.25 | E18: =D18/$D$14 -> 0.35763248 | H18: IBS/CBS pago | I18: =+I17*B7*B9 -> 419.1705 | J18: =J17*$B$9 -> 2.1238e-06 | K18: =K17*$B$9*B7 -> 5868.387
A19: (-) Despesas | B19: =-F3*I3 -> -2500 | C19: =B19/$B$14 -> -0.05 | D19: =-I17 -> -2138.625 | E19: =D19/$D$14 -> -0.045883394 | H19: Tot. Desp.Depois | I19: =I17+I18 -> 2557.7955 | J19: =J17+J18 -> 9.7088e-06 | K19: =K17+K18 -> 35809.137
A20: Lucro Antes do IRPJ e CSLL | B20: =SUM(B18:B19) -> 9110.0001 | C20: =B20/$B$14 -> 0.1822 | D20: =SUM(D18:D19) -> 14530.625 | E20: =D20/$D$14 -> 0.31174909
A21: (-) IRPJ e CSLL | B21: =-IF(B20<=0,0,B20*0.24)+IF(B20>240000,(B20-240000)*0.1) -> -2186.4 | C21: =B21/$B$14 -> -0.043728 | D21: =-IF(D20<=0,0,D20*0.24)+IF(D20>240000,(D20-240000)*0.1) -> -3487.35 | E21: =D21/$D$14 -> -0.074819781
A22: Lucro Líquido | B22: =SUM(B20:B21) -> 6923.6001 | C22: =B22/$B$14 -> 0.138472 | D22: =SUM(D20:D21) -> 11043.275 | E22: =D22/$D$14 -> 0.23692931
A24: ="**Obs: O valor do CMV é reduzido, pois os produtos do fornecedor também irão retirar os impostos sobre o consumo dos seus preços. Desse modo o resultado líquido do exerício foi de R$ " & TEXT(D22-B22, "#.##0,00") & " maior do que antes da reforma, ou seja " & TEXT(((D22-B22)/D22)*100, "0,00") & "% a mais de lucros com a modificação dos impostos" -> **Obs: O valor do CMV é reduzido, pois os produtos do fornecedor também irão retirar os impostos sobre o consumo dos seus preços. Desse modo o resultado líquido do exerício foi de R$ 4.119,68 maior do que antes da reforma, ou seja 37,30% a mais de lucros com a modificação dos impostos | I24: 100 | J24: 97 | K24: 102
I25: =+I24*1.27 -> 127 | J25: =+J24*1.27 -> 123.19 | K25: =+K24*1.27 -> 129.54
I27: 27
A28: Premissas da Planilha e pressupostos para a planilha:
A29: 1) Não há como saber qual o percentual de impostos serão deduzidos das despesas para ter o preço sem impostos. Se tiverem ICMS a carga tributária média pode estar entre 7 a 12% (carga tributária não alíquota), eu fiz médias que estão no comentário da célula)
A31: 2) Parti do pressuposto de que os produtos e despesas receberão após a reforma, o percentual de IBS/CBS, por que os totais na DRE irão receber aumentos nos preços (mas, ao mesmo tempo, redução dos créditos desse IBS/CBS, pois as empresas terão créditos financeiros sobre essas despesas e custos, com excessão de folha de pagamento). Por isso coloquei um percentual máximo de despesas com direito a crédito, pra excluir folha.
A33: 3) Parti do pré-suposto que se voce tem uma empresa de serviços, o seu custo do serviço prestado, terá uma redução de imposto igual a que voce incluiu na sua própria redução de impostos (ISS, PIS, COFINS). E caso, voce seja revendedor ou indústria, a redução do CMV será a mesma da sua própria empresa, pois voce compra com ICMS, PIS, COFINS IPI e ISS (de serviços tomados), também irá ter reduzidos esses mesmos impostos dos seus fornecedores de matéria prima ou produto para revenda.
A35: 4) Inicialmente a empresa terá um reflexo direto no seu caixa em dois aspectos:
A37: 1º) Ela irá ter uma redução imediata de PIS, COFINS, ISS, ICMS e IPI sobre tudo que ela adquirir ou serviços;
A38: 2º) Ela irá pagar 27% sobre tudo que ela adquirir produtos ou tomar de serviços;
A39: 3º) Ela irá se creditar, em nuvem, tendo em conta de IBS/CBS a recuperar no ativo da empresa, todo o imposto pago sobre esses produtos/serviços, e estes impostos NÃO coporão a DRE (demonstração de resultados) da empresa, porque não são despesas, mas sim valores que a empresa vai receber de volta na sua c/c.

Sheet LUCRO PRESUMIDO
A1: Demonstração do Resultado do Exercício Comparativa Reforma - LUCRO PRESUMIDO
A2: www.reformatributaria.inf.br
A3: Faturamento antes Reforma (total) | B3: =SUM(B4+B5) -> 50000 | D3: Redução ICMS/ISS/Pis/Cof Desp. | E3: ='LUCRO REAL'!E7 -> 0.2065
A4: Faturamento Produto | B4: ='LUCRO REAL'!B3 -> 0.0001 | D4: CMV Percentual | E4: ='LUCRO REAL'!F5 -> 0.1
A5: Faturamento Serviços | B5: ='LUCRO REAL'!B4 -> 50000 | D5: Custo Serviços | E5: ='LUCRO REAL'!F4 -> 0.7
A6: Faturamento Pós-Reforma | B6: =B3-B3*C7 -> 46720 | D6: Despesas Percentual | E6: ='LUCRO REAL'!F3 -> 0.05
B7: Impostos Extintos (PIS, COFINS, ICMS, IPI,ISSQN)* | C7: =3.62%+2.94% -> 0.0656 | D7: IRPJ Percentual | E7: 0.15
A8: Percentual Desp. c/ Dir. a Crédito de IBS/CBS | B8: ='LUCRO REAL'!B7 -> 0.7 | D8: CSLL Percentual | E8: 0.09
A9: Imp. Extintos (PIS, COFINS, ICMS, IPI,ISS) CMV | B9: ='LUCRO REAL'!B8 -> 0.2415
B10: Alíquota IBS/CBS | C10: ='LUCRO REAL'!B9 -> 0.28
A12: Demonstração do Resultado do Exercício Comparativa - LUCRO PRESUMIDO
A14: Descrição | B14: Antes | C14: % | D14: Depois | E14: % | G14: Teste de Redução dos Valores após reforma
A15: Receita Bruta | B15: =+B3 -> 50000 | C15: =B15/$B$15 -> 1 | D15: =+B17 -> 46720 | E15: =D15/$D$15 -> 1 | I15: Desp. | J15: CMV | K15: Custo Serviço
A16: (-) Deduções (ICMS, PIS, COFINS, IPI , ISS) | B16: =-B3*C7 -> -3280 | C16: =B16/$B$15 -> -0.0656 | D16: 0 | E16: =D16/$D$15 -> 0 | H16: Total Despesas Antes | I16: =(SUM(B4:B5)*E6) -> 2500 | J16: =(SUM(B4)*E4) -> 1e-05 | K16: =+(B5*E5) -> 35000
A17: Receita Líquida | B17: =SUM(B15:B16) -> 46720 | C17: =B17/$B$15 -> 0.9344 | D17: =SUM(D15:D16) -> 46720 | E17: =D17/$D$15 -> 1 | H17: Redução de Impostos Extintos | I17: =-(I16*B8*E3) -> -361.375 | J17: =-J16*B9 -> -2.415e-06 | K17: =-K16*E3*B8 -> -5059.25
A18: (=) CMV + CSV | B18: =-(B4*E4)-(B5*E5) -> -35000 | C18: =B18/$B$15 -> -0.7 | D18: =-J18-K18 -> -29940.75 | E18: =D18/$D$15 -> -0.64085509 | F18: ** | H18: Desp. (-) Impostos | I18: =SUM(I16:I17) -> 2138.625 | J18: =SUM(J16:J17) -> 7.585e-06 | K18: =SUM(K16:K17) -> 29940.75
A19: Margem de Contribuição | B19: =SUM(B17:B18) -> 11720 | C19: =B19/$B$15 -> 0.2344 | D19: =SUM(D17:D18) -> 16779.25 | E19: =D19/$D$15 -> 0.35914491 | H19: IBS/CBS pago | I19: =+I18*B8*C10 -> 419.1705 | J19: =J18*C10 -> 2.1238e-06 | K19: =K18*C10*B8 -> 5868.387
A20: (-) Despesas | B20: =-E6*B3 -> -2500 | C20: =B20/$B$15 -> -0.05 | D20: =-I18 -> -2138.625 | E20: =D20/$D$15 -> -0.045775364 | H20: Tot. Desp.Depois | I20: =I18+I19 -> 2557.7955 | J20: =J18+J19 -> 9.7088e-06 | K20: =K18+K19 -> 35809.137
A21: Lucro Antes do IRPJ e CSLL | B21: =SUM(B19:B20) -> 9220.0001 | C21: =B21/$B$15 -> 0.1844 | D21: =SUM(D19:D20) -> 14640.625 | E21: =D21/$D$15 -> 0.31336954
A22: (-) IRPJ e CSLL | B22: =((B4*0.08*E7)+(B5*0.32*E7)+(B4*0.12*E8)+(B5*0.32*E8)+IF(H25>240000,(H25-240000)*0.1,0))*-1 -> -3840 | C22: =B22/$B$15 -> -0.0768 | D22: =((B4*0.08*E7)+(B5*0.32*E7)+(B4*0.12*E8)+(B5*0.32*E8)+IF(H25>240000,(H25-240000)*0.1,0))*-1 -> -3840 | E22: =D22/$D$15 -> -0.082191781 | H22: =B4*0.08 -> 8e-06 | I22: b.c p / adicional
A23: Lucro Líquido | B23: =SUM(B21:B22) -> 5380.0001 | C23: =B23/$B$15 -> 0.1076 | D23: =SUM(D21:D22) -> 10800.625 | E23: =D23/$D$15 -> 0.23117776 | H23: =B5*0.32 -> 16000 | I23: b.c p / adicional
A25: ="**Obs: O valor do CMV é reduzido, pois os produtos do fornecedor também irão retirar os impostos sobre o consumo dos seus preços. Desse modo o resultado líquido do exerício foi de R$ " & TEXT(D23-B23, "#.##0,00") & " maior do que antes da reforma, ou seja " & TEXT(((D23-B23)/D23)*100, "0,00") & "% a mais de lucros com a modificação dos impostos" -> **Obs: O valor do CMV é reduzido, pois os produtos do fornecedor também irão retirar os impostos sobre o consumo dos seus preços. Desse modo o resultado líquido do exerício foi de R$ 5.420,63 maior do que antes da reforma, ou seja 50,19% a mais de lucros com a modificação dos impostos | H25: =SUM(H22:H23) -> 16000 | I25: b.c p / adicional
A28: Premissas da Planilha e pressupostos para a planilha:
A29: 1) Não há como saber qual o percentual de impostos serão deduzidos das despesas para ter o preço sem impostos. Se tiverem ICMS a carga tributária média pode estar entre 7 a 12% (carga tributária não alíquota), eu fiz médias que estão no comentário da célula)
A31: 2) Parti do pressuposto de que os produtos e despesas receberão após a reforma, o percentual de IBS/CBS, por que os totais na DRE irão receber aumetnos nos preços (mas, ao mesmo tempo, redução dos créditos desse IBS/CBS, pois as empresas terão créditos financeiros sobre essas despesas e custos, com excessão de folha de pagamento). Por isso coloquei um percentual máximo de despesas com direito a crédito, pra excluir folha.
A33: 3) Parti do pré-suposto que se voce tem uma empresa de serviços, o seu custo do serviço prestado, terá uma redução de imposto igual a que voce incluiu na sua própria redução de impostos (ISS, PIS, COFINS). E caso, voce seja revendedor ou indústria, a redução do CMV será a mesma da sua própria empresa, pois voce compra com ICMS, PIS, COFINS IPI e ISS (de serviços tomados), também irá ter reduzidos esses mesmos impostos dos seus fornecedores de matéria prima ou produto para revenda.
A35: 4) Inicialmente a empresa terá um reflexo direto no seu caixa em dois aspectos:
A37: 1º) Ela irá ter uma redução imediata de PIS, COFINS, ISS, ICMS e IPI sobre tudo que ela adquirir ou serviços;
A38: 2º) Ela irá pagar 27% sobre tudo que ela adquirir produtos ou tomar de serviços;
A39: 3º) Ela irá se creditar, em nuvem, tendo em conta de IBS/CBS a recuperar no ativo da empresa, todo o imposto pago sobre esses produtos/serviços, e estes impostos NÃO coporão a DRE (demonstração de resultados) da empresa, porque não são despesas, mas sim valores que a empresa vai receber de volta na sua c/c.

Sheet SIMPLES NACIONAL (IBS-CBS)
A1: Demonstração do Resultado do Exercício Comparativa Reforma - SIMPLES NACIONAL
A2: www.reformatributaria.inf.br
A3: Faturamento antes Reforma (total) | B3: =SUM(B4+B5) -> 50000 | D3: CMV Percentual | E3: ='LUCRO PRESUMIDO'!E4 -> 0.1
A4: Faturamento Produto | B4: ='LUCRO PRESUMIDO'!B4 -> 0.0001 | D4: Custo Serviço Percentual | E4: ='LUCRO PRESUMIDO'!E5 -> 0.7
A5: Faturamento Serviços | B5: ='LUCRO PRESUMIDO'!B5 -> 50000 | D5: Despesas Percentual | E5: ='LUCRO PRESUMIDO'!E6 -> 0.05
A6: Faturamento Pós-Reforma | B6: =B3-B3*B7 -> 46555 | D6: Simule as alíquotas aqui: | E6: https://canaltributario.com.br/simulador/
A7: Imp. Extintos (PIS, COFINS, ICMS, IPI,ISS) DAS | B7: =14.02%-E7-E8-E9 -> 0.0689 | D7: IRPJ (Extrato do Simples) | E7: 0.0056
A8: Percentual Desp. c/ Dir. a Crédito de IBS/CBS | B8: ='LUCRO PRESUMIDO'!B8 -> 0.7 | D8: CSLL (Extrato do Simples) | E8: 0.0049
D9: CPP-INSS (Extrato do Simples) | E9: 0.0608
A10: Redução ICMS/ISS/Pis/Cof Desp. | B10: ='LUCRO PRESUMIDO'!E3 -> 0.2065
A11: Imp. Extintos (PIS, COFINS, ICMS, IPI,ISS) CMV | B11: ='LUCRO PRESUMIDO'!B9 -> 0.2415
B12: Alíquota IBS/CBS | C12: ='LUCRO PRESUMIDO'!C10 -> 0.28
A14: Demonstração do Resultado do Exercício Comparativa - SIMPLES NACIONAL
A16: Descrição | B16: Antes | C16: % | D16: Depois | E16: % | G16: Teste de Redução dos Valores após reforma
A17: Receita Bruta | B17: =+B3 -> 50000 | C17: =B17/$B$17 -> 1 | D17: =+B19 -> 46555 | E17: =D17/$D$17 -> 1 | I17: Desp. | J17: CMV | K17: Custo Serviço
A18: (-) Deduções (ICMS, PIS, COFINS, IPI , ISS) | B18: =-B3*B7 -> -3445 | C18: =B18/$B$17 -> -0.0689 | D18: 0 | E18: =D18/$D$17 -> 0 | H18: Total Despesas Antes | I18: =(SUM(B4:B5)*E5) -> 2500 | J18: =(SUM(B4)*E3) -> 1e-05 | K18: =+(B5*E4) -> 35000
A19: Receita Líquida | B19: =SUM(B17:B18) -> 46555 | C19: =B19/$B$17 -> 0.9311 | D19: =SUM(D17:D18) -> 46555 | E19: =D19/$D$17 -> 1 | H19: Redução de Impostos Extintos | I19: =-(I18*B8*B10) -> -361.375 | J19: =-J18*B11 -> -2.415e-06 | K19: =-K18*E4*B8*B10 -> -3541.475
A20: (=) CMV + CSV | B20: =-E3*B4-B5*E4 -> -35000 | C20: =B20/$B$17 -> -0.7 | D20: =-J20-K20 -> -31458.525 | E20: =D20/$D$17 -> -0.67572817 | F20: ** | H20: Desp. (-) Impostos | I20: =SUM(I18:I19) -> 2138.625 | J20: =SUM(J18:J19) -> 7.585e-06 | K20: =SUM(K18:K19) -> 31458.525
A21: Margem de Contribuição | B21: =SUM(B19:B20) -> 11555 | C21: =B21/$B$17 -> 0.2311 | D21: =SUM(D19:D20) -> 15096.475 | E21: =D21/$D$17 -> 0.32427183 | H21: IBS/CBS pago | I21: =+I20*B8*C12 -> 419.1705 | J21: =J20*C12 -> 2.1238e-06 | K21: =K20*C12*B8 -> 6165.8709
A22: (-) Despesas (Já Incluída CPP-Inss) | B22: =-E5*B3-(E9*B3) -> -5540 | C22: =B22/$B$17 -> -0.1108 | D22: =-I20-(E9*B3) -> -5178.625 | E22: =D22/$D$17 -> -0.11123671 | H22: Tot. Desp.Depois | I22: =I20+I21 -> 2557.7955 | J22: =J20+J21 -> 9.7088e-06 | K22: =K20+K21 -> 37624.396
A23: Lucro Antes do IRPJ e CSLL | B23: =SUM(B21:B22) -> 6015.0001 | C23: =B23/$B$17 -> 0.1203 | D23: =SUM(D21:D22) -> 9917.8501 | E23: =D23/$D$17 -> 0.21303512
A24: (-) IRPJ e CSLL | B24: =-B3*E7-B3*E8 -> -525 | C24: =B24/$B$17 -> -0.0105 | D24: =-B3*E7-B3*E8 -> -525 | E24: =D24/$D$17 -> -0.011276984
A25: Lucro Líquido | B25: =SUM(B23:B24) -> 5490.0001 | C25: =B25/$B$17 -> 0.1098 | D25: =SUM(D23:D24) -> 9392.8501 | E25: =D25/$D$17 -> 0.20175814
A27: ="**Obs: O valor do CMV é reduzido, pois os produtos do fornecedor também irão retirar os impostos sobre o consumo dos seus preços. Desse modo o resultado líquido do exerício foi de R$ " & TEXT(D25-B25, "#.##0,00") & " maior do que antes da reforma, ou seja " & TEXT(((D25-B25)/D25)*100, "0,00") & "% a mais de lucros com a modificação dos impostos" -> **Obs: O valor do CMV é reduzido, pois os produtos do fornecedor também irão retirar os impostos sobre o consumo dos seus preços. Desse modo o resultado líquido do exerício foi de R$ 3.902,85 maior do que antes da reforma, ou seja 41,55% a mais de lucros com a modificação dos impostos
A31: Premissas da Planilha e pressupostos para a planilha:
A32: 1) Não há como saber qual o percentual de impostos serão deduzidos das despesas para ter o preço sem impostos. Se tiverem ICMS a carga tributária média pode estar entre 7 a 12% (carga tributária não alíquota), eu fiz médias que estão no comentário da célula)
A34: 2) Parti do pressuposto de que os produtos e despesas receberão após a reforma, o percentual de IBS/CBS, por que os totais na DRE irão receber aumetnos nos preços (mas, ao mesmo tempo, redução dos créditos desse IBS/CBS, pois as empresas terão créditos financeiros sobre essas despesas e custos, com excessão de folha de pagamento). Por isso coloquei um percentual máximo de despesas com direito a crédito, pra excluir folha.
A36: 3) Parti do pré-suposto que se voce tem uma empresa de serviços, o seu custo do serviço prestado, terá uma redução de imposto igual a que voce incluiu na sua própria redução de impostos (ISS, PIS, COFINS). E caso, voce seja revendedor ou indústria, a redução do CMV será a mesma da sua própria empresa, pois voce compra com ICMS, PIS, COFINS IPI e ISS (de serviços tomados), também irá ter reduzidos esses mesmos impostos dos seus fornecedores de matéria prima ou produto para revenda.
A38: 4) Inicialmente a empresa terá um reflexo direto no seu caixa em dois aspectos:
A40: 1º) Ela irá ter uma redução imediata de PIS, COFINS, ISS, ICMS e IPI sobre tudo que ela adquirir ou serviços;
A41: 2º) Ela irá pagar 27% sobre tudo que ela adquirir produtos ou tomar de serviços;
A42: 3º) Ela irá se creditar, em nuvem, tendo em conta de IBS/CBS a recuperar no ativo da empresa, todo o imposto pago sobre esses produtos/serviços, e estes impostos NÃO coporão a DRE (demonstração de resultados) da empresa, porque não são despesas, mas sim valores que a empresa vai receber de volta na sua c/c.

Sheet SIMP, NACIONAL sem créd IBS
A1: Demonstração do Resultado Exerc. Comparativa Reforma - SIMPLES NACIONAL S/cred.
A2: www.reformatributaria.inf.br
A3: Faturamento antes Reforma (total) | B3: =SUM(B4+B5) -> 50000 | D3: CMV Percentual | E3: ='SIMPLES NACIONAL (IBS-CBS)'!E3 -> 0.1
A4: Faturamento Produto | B4: ='SIMPLES NACIONAL (IBS-CBS)'!B4 -> 0.0001 | D4: Custo Serviço Percentual | E4: ='SIMPLES NACIONAL (IBS-CBS)'!E4 -> 0.7
A5: Faturamento Serviços | B5: ='SIMPLES NACIONAL (IBS-CBS)'!B5 -> 50000 | D5: Despesas Percentual | E5: ='SIMPLES NACIONAL (IBS-CBS)'!E5 -> 0.05
A6: Faturamento Pós-Reforma | B6: =B3-B3*B7 -> 46556 | D6: Simule as alíquotas aqui: | E6: https://canaltributario.com.br/simulador/
A7: Imp. Extintos (PIS, COFINS, ICMS, IPI,ISS) DAS | B7: =14.02%-E7-E8-E9 -> 0.06888 | D7: IRPJ (Extrato do Simples) | E7: 0.00561
A8: Percentual Desp. c/ Dir. a Crédito de IBS/CBS | B8: ='SIMPLES NACIONAL (IBS-CBS)'!B8 -> 0.7 | D8: CSLL (Extrato do Simples) | E8: 0.00491
A9: Redução ICMS/ISS/Pis/Cof Desp. | B9: ='SIMPLES NACIONAL (IBS-CBS)'!B10 -> 0.2065 | D9: CPP-INSS (Extrato do Simples) | E9: 0.0608
A10: Imp. Extintos (PIS, COFINS, ICMS, IPI,ISS) CMV | B10: ='SIMPLES NACIONAL (IBS-CBS)'!B11 -> 0.2415 | G10: =14.3*(15.33%+0.17%) -> 2.2165
B11: Alíquota IBS/CBS | C11: 0.265 | D11: IBS/CBS no DAS | E11: =+(21.76%+0.24)*14.3% -> 0.0654368 | F11: <-Tabela IBS/CBS Faixa 6
A12: Demonstração do Resultado do Exercício Comparativa - SIMPLES NACIONAL
A13: Sem créditos algum de IBS/CBS
A14: Descrição | B14: Antes | C14: % | D14: Depois | E14: % | G14: Teste de Redução dos Valores após reforma
A15: Receita Bruta | B15: =+B3 -> 50000 | C15: =B15/$B$15 -> 1 | D15: =+B15 -> 50000 | E15: =D15/$D$15 -> 1 | I15: Desp. | J15: CMV | K15: Custo Serviço
A16: (-) Ded. (ICMS, PIS, COF, IPI , ISS) CBS/IBS | B16: =-B3*B7 -> -3444 | C16: =B16/$B$15 -> -0.06888 | D16: =-D15*E11 -> -3271.84 | E16: =D16/$D$15 -> -0.0654368 | H16: Total Despesas Antes | I16: =(SUM(B4:B5)*E5) -> 2500 | J16: =(SUM(B4)*E3) -> 1e-05 | K16: =+(B5*E4) -> 35000
A17: Receita Líquida | B17: =SUM(B15:B16) -> 46556 | C17: =B17/$B$15 -> 0.93112 | D17: =SUM(D15:D16) -> 46728.16 | E17: =D17/$D$15 -> 0.9345632 | H17: Redução de Impostos Extintos | I17: =-(I16*B9*B8) -> -361.375 | J17: =-J16*B10 -> -2.415e-06 | K17: =-K16*E4*B8*B9 -> -3541.475
A18: (=) CMV + CSV | B18: =-E3*B4-B5*E4 -> -35000 | C18: =B18/$B$15 -> -0.7 | D18: =-J20-K20 -> -39795.034 | E18: =D18/$D$15 -> -0.79590068 | F18: ** | H18: Desp. (-) Impostos | I18: =SUM(I16:I17) -> 2138.625 | J18: =SUM(J16:J17) -> 7.585e-06 | K18: =SUM(K16:K17) -> 31458.525
A19: Margem de Contribuição | B19: =SUM(B17:B18) -> 11556 | C19: =B19/$B$15 -> 0.23112 | D19: =SUM(D17:D18) -> 6933.126 | E19: =D19/$D$15 -> 0.13866252 | H19: IBS/CBS pago | I19: =+I18*C11 -> 566.73563 | J19: =J18*C11 -> 2.010025e-06 | K19: =K18*C11 -> 8336.5091
A20: (-) Despesas (Já Incluída CPP-Inss) | B20: =-E5*B3-(E9*B3) -> -5540 | C20: =B20/$B$15 -> -0.1108 | D20: =-I20-(E9*B3) -> -5745.3606 | E20: =D20/$D$15 -> -0.11490721 | H20: Tot. Desp.Depois | I20: =I18+I19 -> 2705.3606 | J20: =J18+J19 -> 9.595025e-06 | K20: =K18+K19 -> 39795.034
A21: Lucro Antes do IRPJ e CSLL | B21: =SUM(B19:B20) -> 6016.0001 | C21: =B21/$B$15 -> 0.12032 | D21: =SUM(D19:D20) -> 1187.7653 | E21: =D21/$D$15 -> 0.023755307
A22: (-) IRPJ e CSLL | B22: =-B3*E7-B3*E8 -> -526 | C22: =B22/$B$15 -> -0.01052 | D22: =-B3*E7-B3*E8 -> -526 | E22: =D22/$D$15 -> -0.01052 | G22: Artigo 160, § 2º:
A23: Lucro Líquido | B23: =SUM(B21:B22) -> 5490.0001 | C23: =B23/$B$15 -> 0.1098 | D23: =SUM(D21:D22) -> 661.76533 | E23: =D23/$D$15 -> 0.013235307 | G23: “Os créditos presumidos de IBS e de CBS que trata o caput serão calculados mediante aplicação dos seguintes percentuais sobre o valor da aquisição registrado em documento admitido pela administração tributária na forma do regulamento:
A25: ="**Obs: O valor do CMV é reduzido, pois os produtos do fornecedor também irão retirar os impostos sobre o consumo dos seus preços. Desse modo o resultado líquido do exerício foi de R$ " & TEXT(D23-B23, "#.##0,00") & " do que antes da reforma, ou seja " & TEXT(((D23-B23)/D23)*-100, "0,00") & "% de diferença no resultado com a modificação dos impostos" -> **Obs: O valor do CMV é reduzido, pois os produtos do fornecedor também irão retirar os impostos sobre o consumo dos seus preços. Desse modo o resultado líquido do exerício foi de R$ -4.828,23 do que antes da reforma, ou seja 729,60% de diferença no resultado com a modificação dos impostos | G25: I - para o crédito presumido de IBS, 13% (treze por cento);
G26: II - para o crédito presumido de CBS, 7% (sete por cento).”
A29: Premissas da Planilha e pressupostos para a planilha:
A30: 1) Não há como saber qual o percentual de impostos serão deduzidos das despesas para ter o preço sem impostos. Se tiverem ICMS a carga tributária média pode estar entre 7 a 12% (carga tributária não alíquota), eu fiz médias que estão no comentário da célula) | G30: Sim, você está correto. A utilização dos créditos presumidos pode ser entendida como uma forma de ajustar a alíquota efetiva de IBS e CBS dentro do Simples Nacional, resultando em uma alíquota reduzida. Isso é feito para que a carga tributária final para as empresas optantes pelo Simples Nacional seja proporcional e justa, considerando a simplificação do regime.
G31: ### Cálculo da Alíquota Efetiva
A32: 2) Parti do pressuposto de que os produtos e despesas receberão após a reforma, o percentual de IBS/CBS, por que os totais na DRE irão receber aumetnos nos preços (mas, ao mesmo tempo, redução dos créditos desse IBS/CBS, pois as empresas terão créditos financeiros sobre essas despesas e custos, com excessão de folha de pagamento). Por isso coloquei um percentual máximo de despesas com direito a crédito, pra excluir folha.
G33: Vamos detalhar como a alíquota efetiva pode ser determinada utilizando os créditos presumidos.
A34: 3) Parti do pré-suposto que se voce tem uma empresa de serviços, o seu custo do serviço prestado, terá uma redução de imposto igual a que voce incluiu na sua própria redução de impostos (ISS, PIS, COFINS). E caso, voce seja revendedor ou indústria, a redução do CMV será a mesma da sua própria empresa, pois voce compra com ICMS, PIS, COFINS IPI e ISS (de serviços tomados), também irá ter reduzidos esses mesmos impostos dos seus fornecedores de matéria prima ou produto para revenda.
G35: 1. **Alíquota Base de IBS e CBS**:
A36: 4) Inicialmente a empresa terá um reflexo direto no seu caixa em dois aspectos: | G36: - Alíquota combinada: 26,5%
A38: 1º) Ela irá ter uma redução imediata de PIS, COFINS, ISS, ICMS e IPI sobre tudo que ela adquirir ou serviços;
A39: 2º) Ela irá pagar 26,5% sobre tudo que ela adquirir produtos ou tomar de serviços; | G39: 2. **Créditos Presumidos**:
A40: 3º) Ela irá se creditar, em nuvem, tendo em conta de IBS/CBS a recuperar no ativo da empresa, todo o imposto pago sobre esses produtos/serviços, e estes impostos NÃO coporão a DRE (demonstração de resultados) da empresa, porque não são despesas, mas sim valores que a empresa vai receber de volta na sua c/c. | G40: - Crédito presumido de IBS: 13%
G41: - Crédito presumido de CBS: 7%
G42: - Crédito presumido total: 20%
A43: 5) Cálculo de IBS e CBS quando a empresa paga dentro do DAS
A44: O Simples Nacional para calcular a alíquota final de IBS/CBS sobre o faturamento, parte da presunção de 13% de CBS e 7% de Ibs. Assim Por exemplo num volume de 2,4 milhões de faturaento chega-se a uma alíquota efetiva dentro do DAS de 6,5% aproximadamente de CBS e IBS a pagar s/ o faturamento. | G44: 3. **Alíquota Efetiva**:
...

Sheet COMPARATIVO
A1: CASE EMPRESA DE SERVIÇOS SIMPLES - FATURANDO 1,8 MILHÕES POR ANO
A2: www.reformatributaria.inf.br
C4: IBS/CBS
C5: FORA DO DAS | F5: DENTRO DO DAS
B6: Valor de um produto ou serviço atual | C6: 100 | F6: 100
B7: ( - ) Carga tributária PIS/COF/ICMS/IPI/ISS no SIMPLES | C7: =14.02%-6.08%-0.49%-0.56% -> 0.0689 | F7: =14.02%-6.08%-0.49%-0.56% -> 0.0689
B8: BASE DE CÁLCULO PARA IBS/CBS | C8: =C6*(1-C7) -> 93.11 | F8: =F6*(1-F7) -> 93.11
A10: PREÇO DE VENDA (PÓS REFORMA) | C10: =C8 -> 93.11 | F10: =F8 -> 93.11 | G10: *
B11: ALÍQUOTA IBS | C11: 0.265 | F11: 0.0654
B12: VALOR PAGO PELO CLIENTE | C12: =+C10*(1+C11) -> 117.78415 | F12: =+F10*(1+F11) -> 99.199394
B14: VALOR NO CAIXA DA EMPRESA | C14: =C10 -> 93.11 | F14: =F10 -> 93.11
B16: VALOR DIRETO PRO GOVERNO | C16: =C12-C10 -> 24.67415 | F16: =F12-F10 -> 6.089394
B18: PRÓS de ter o IBS e CBS dentro do DAS | D18: CONTRAS de ter o IBS e CBS dentro do DAS
B19: Valor menor de IBS/CBS pro cliente (PREÇO MENOR) | F19: Não aproveita crédito de IBS/CBS Merc. E Desp
F20: Aumento do CMV/ REDUÇÃO DO LUCRO
F21: Transmite apenas 6% crédito IBS/CBS p/ PJ
A23: * ATENÇÃO: Para a empresa não ter prejuízo, no caso de vender fora do regime regular, ela terá que avaliar que o custo de mercadorias aumentará 26,5% e não terá crédito sobre despesas e custos de serviços, o que tornará sua precificação mais cara e não poderá vender pelo mesmo preço. WWW.REFORMATRIBUTARIA.INF.BR
